<?xml version="1.0"?>

<robot name="visual">
  <link name="base_link">
 <origin xyz="0 0 0 " rpy=" 0 0 0"/>
    <visual>

    </visual>
  </link>

  <link name="Link1">
    <origin xyz="0 0 0" rpy=" 0 0 0"/>
    <visual>

    </visual>
  </link>

  <joint name="joint0" type="revolute">
    <origin xyz="0 0 0" rpy=" 0 0 0"/>
    <parent link="base_link"/>
    <child link="Link1"/>
    <limit effort="1.0" lower="0" upper="6" velocity="1.0"/>
    <axis xyz = "0 0 1"/>
  </joint>

  <link name="Link2">
    <origin xyz="0 0 0 " rpy=" 0 0 0"/>
     <visual>
    </visual>
  </link>

  <joint name="joint1" type="revolute">
    <origin xyz="0 0 .168" rpy="-1.57 0 0"/>
    <parent link="Link1"/>
    <child link="Link2"/>
    <limit effort="1.0" lower="0" upper="6" velocity="1.0"/>
    <axis xyz = "0 0 1"/>
  </joint>

  <link name="Link3">
    <origin xyz=".24 0 0 " rpy=" 0 0 0"/>
     <visual>
    </visual>
  </link>


  <joint name="joint2" type="revolute">
    <origin xyz=".24 0 0" rpy=" 0 0 0"/>
    <parent link="Link2"/>
    <child link="Link3"/>
    <limit effort="1.0" lower="0" upper="6" velocity="1.0"/>
    <axis xyz = "0 0 1"/>
  </joint>


  <link name="EE">
    <origin xyz="0 0 0 " rpy=" 0 0 0"/>
     <visual>
    </visual>
  </link>

  <joint name="EE" type="fixed">
    <origin xyz=".24 0 0" rpy=" 0 0 0"/>
    <parent link="Link3"/>
    <child link="EE"/>
    <limit effort="1.0" lower="0" upper="6" velocity="1.0"/>
    <axis xyz = "0 0 1"/>
  </joint>


</robot>
